2024-09-10 19:38:50,667 INFO: Microblog startup [in /home/user/Documentos/FP_HBTN_Microblog/microblog/app/__init__.py:43]
2024-09-11 17:28:13,650 INFO: Microblog startup [in /home/user/Documentos/FP_HBTN_Microblog/flaskyblog/app/__init__.py:43]
2024-09-11 17:46:23,018 INFO: Microblog startup [in /home/user/Documentos/FP_HBTN_Microblog/flaskyblog/app/__init__.py:43]
2024-09-11 17:47:21,452 INFO: Microblog startup [in /home/user/Documentos/FP_HBTN_Microblog/flaskyblog/app/__init__.py:43]
2024-09-11 17:47:49,880 INFO: Microblog startup [in /home/user/Documentos/FP_HBTN_Microblog/flaskyblog/app/__init__.py:43]
2024-09-11 18:26:56,508 INFO: Microblog startup [in /home/user/Documentos/FP_HBTN_Microblog/flaskyblog/app/__init__.py:43]
2024-09-11 18:29:05,608 INFO: Microblog startup [in /home/user/Documentos/FP_HBTN_Microblog/flaskyblog/app/__init__.py:43]
2024-09-11 18:44:11,613 INFO: Microblog startup [in /home/user/Documentos/FP_HBTN_Microblog/flaskyblog/app/__init__.py:43]
2024-09-11 18:57:14,973 INFO: Microblog startup [in /home/user/Documentos/FP_HBTN_Microblog/flaskyblog/app/__init__.py:43]
2024-09-11 19:43:30,428 INFO: Microblog startup [in /home/user/Documentos/FP_HBTN_Microblog/flaskyblog/app/__init__.py:43]
2024-09-11 19:44:08,670 ERROR: Exception on /follow/susan [GET] [in /home/user/Documentos/FP_HBTN_Microblog/flaskyblog/venv/lib/python3.10/site-packages/flask/app.py:825]
Traceback (most recent call last):
  File "/home/user/Documentos/FP_HBTN_Microblog/flaskyblog/venv/lib/python3.10/site-packages/flask/app.py", line 1455, in wsgi_app
    response = self.full_dispatch_request()
  File "/home/user/Documentos/FP_HBTN_Microblog/flaskyblog/venv/lib/python3.10/site-packages/flask/app.py", line 869, in full_dispatch_request
    rv = self.handle_user_exception(e)
  File "/home/user/Documentos/FP_HBTN_Microblog/flaskyblog/venv/lib/python3.10/site-packages/flask/app.py", line 867, in full_dispatch_request
    rv = self.dispatch_request()
  File "/home/user/Documentos/FP_HBTN_Microblog/flaskyblog/venv/lib/python3.10/site-packages/flask/app.py", line 852, in dispatch_request
    return self.ensure_sync(self.view_functions[rule.endpoint])(**view_args)
  File "/home/user/Documentos/FP_HBTN_Microblog/flaskyblog/venv/lib/python3.10/site-packages/flask_login/utils.py", line 290, in decorated_view
    return current_app.ensure_sync(func)(*args, **kwargs)
  File "/home/user/Documentos/FP_HBTN_Microblog/flaskyblog/app/routes.py", line 98, in follow
    if user in None:
TypeError: argument of type 'NoneType' is not iterable
2024-09-11 19:44:32,731 ERROR: Exception on /follow/susan [GET] [in /home/user/Documentos/FP_HBTN_Microblog/flaskyblog/venv/lib/python3.10/site-packages/flask/app.py:825]
Traceback (most recent call last):
  File "/home/user/Documentos/FP_HBTN_Microblog/flaskyblog/venv/lib/python3.10/site-packages/flask/app.py", line 1455, in wsgi_app
    response = self.full_dispatch_request()
  File "/home/user/Documentos/FP_HBTN_Microblog/flaskyblog/venv/lib/python3.10/site-packages/flask/app.py", line 869, in full_dispatch_request
    rv = self.handle_user_exception(e)
  File "/home/user/Documentos/FP_HBTN_Microblog/flaskyblog/venv/lib/python3.10/site-packages/flask/app.py", line 867, in full_dispatch_request
    rv = self.dispatch_request()
  File "/home/user/Documentos/FP_HBTN_Microblog/flaskyblog/venv/lib/python3.10/site-packages/flask/app.py", line 852, in dispatch_request
    return self.ensure_sync(self.view_functions[rule.endpoint])(**view_args)
  File "/home/user/Documentos/FP_HBTN_Microblog/flaskyblog/venv/lib/python3.10/site-packages/flask_login/utils.py", line 290, in decorated_view
    return current_app.ensure_sync(func)(*args, **kwargs)
  File "/home/user/Documentos/FP_HBTN_Microblog/flaskyblog/app/routes.py", line 98, in follow
    if user in None:
TypeError: argument of type 'NoneType' is not iterable
2024-09-11 19:45:31,630 INFO: Microblog startup [in /home/user/Documentos/FP_HBTN_Microblog/flaskyblog/app/__init__.py:43]
2024-09-11 19:45:42,901 ERROR: Exception on /follow/susan [GET] [in /home/user/Documentos/FP_HBTN_Microblog/flaskyblog/venv/lib/python3.10/site-packages/flask/app.py:825]
Traceback (most recent call last):
  File "/home/user/Documentos/FP_HBTN_Microblog/flaskyblog/venv/lib/python3.10/site-packages/flask/app.py", line 1455, in wsgi_app
    response = self.full_dispatch_request()
  File "/home/user/Documentos/FP_HBTN_Microblog/flaskyblog/venv/lib/python3.10/site-packages/flask/app.py", line 869, in full_dispatch_request
    rv = self.handle_user_exception(e)
  File "/home/user/Documentos/FP_HBTN_Microblog/flaskyblog/venv/lib/python3.10/site-packages/flask/app.py", line 867, in full_dispatch_request
    rv = self.dispatch_request()
  File "/home/user/Documentos/FP_HBTN_Microblog/flaskyblog/venv/lib/python3.10/site-packages/flask/app.py", line 852, in dispatch_request
    return self.ensure_sync(self.view_functions[rule.endpoint])(**view_args)
  File "/home/user/Documentos/FP_HBTN_Microblog/flaskyblog/venv/lib/python3.10/site-packages/flask_login/utils.py", line 290, in decorated_view
    return current_app.ensure_sync(func)(*args, **kwargs)
  File "/home/user/Documentos/FP_HBTN_Microblog/flaskyblog/app/routes.py", line 105, in follow
    db.sessino.commit()
  File "/home/user/Documentos/FP_HBTN_Microblog/flaskyblog/venv/lib/python3.10/site-packages/flask_sqlalchemy/extension.py", line 1008, in __getattr__
    raise AttributeError(name)
AttributeError: sessino
2024-09-11 19:46:21,087 ERROR: Exception on /follow/susan [GET] [in /home/user/Documentos/FP_HBTN_Microblog/flaskyblog/venv/lib/python3.10/site-packages/flask/app.py:825]
Traceback (most recent call last):
  File "/home/user/Documentos/FP_HBTN_Microblog/flaskyblog/venv/lib/python3.10/site-packages/flask/app.py", line 1455, in wsgi_app
    response = self.full_dispatch_request()
  File "/home/user/Documentos/FP_HBTN_Microblog/flaskyblog/venv/lib/python3.10/site-packages/flask/app.py", line 869, in full_dispatch_request
    rv = self.handle_user_exception(e)
  File "/home/user/Documentos/FP_HBTN_Microblog/flaskyblog/venv/lib/python3.10/site-packages/flask/app.py", line 867, in full_dispatch_request
    rv = self.dispatch_request()
  File "/home/user/Documentos/FP_HBTN_Microblog/flaskyblog/venv/lib/python3.10/site-packages/flask/app.py", line 852, in dispatch_request
    return self.ensure_sync(self.view_functions[rule.endpoint])(**view_args)
  File "/home/user/Documentos/FP_HBTN_Microblog/flaskyblog/venv/lib/python3.10/site-packages/flask_login/utils.py", line 290, in decorated_view
    return current_app.ensure_sync(func)(*args, **kwargs)
  File "/home/user/Documentos/FP_HBTN_Microblog/flaskyblog/app/routes.py", line 105, in follow
    db.sessino.commit()
  File "/home/user/Documentos/FP_HBTN_Microblog/flaskyblog/venv/lib/python3.10/site-packages/flask_sqlalchemy/extension.py", line 1008, in __getattr__
    raise AttributeError(name)
AttributeError: sessino
2024-09-11 19:47:49,637 INFO: Microblog startup [in /home/user/Documentos/FP_HBTN_Microblog/flaskyblog/app/__init__.py:43]
2024-09-11 20:09:11,772 INFO: Microblog startup [in /home/user/Documentos/FP_HBTN_Microblog/flaskyblog/app/__init__.py:43]
2024-09-11 20:13:53,562 INFO: Microblog startup [in /home/user/Documentos/FP_HBTN_Microblog/flaskyblog/app/__init__.py:43]
2024-09-11 20:18:29,373 INFO: Microblog startup [in /home/user/Documentos/FP_HBTN_Microblog/flaskyblog/app/__init__.py:43]
2024-09-13 11:40:52,109 INFO: Microblog startup [in /home/user/Documentos/FP_HBTN_Microblog/flaskyblog/app/__init__.py:43]
2024-09-13 11:53:07,574 INFO: Microblog startup [in /home/user/Documentos/FP_HBTN_Microblog/flaskyblog/app/__init__.py:43]
